Workbook

Sheet file_processing_summary
A1: file_name | B1: file_path | C1: rows_raw | D1: rows_cleaned | E1: columns_raw | F1: columns_final | G1: status
A2: savedrecs_1.xls | B2: C:\Users\Luís Pinto Coelho\Desktop\Dissertação\StudyScreening_Meta-Analysis\data\web_of_science\raw_data\savedrecs_1.xls | C2: 1000 | D2: 1000 | E2: 72 | F2: 25 | G2: ok
A3: savedrecs_2.xls | B3: C:\Users\Luís Pinto Coelho\Desktop\Dissertação\StudyScreening_Meta-Analysis\data\web_of_science\raw_data\savedrecs_2.xls | C3: 1000 | D3: 1000 | E3: 72 | F3: 25 | G3: ok
A4: savedrecs_3.xls | B4: C:\Users\Luís Pinto Coelho\Desktop\Dissertação\StudyScreening_Meta-Analysis\data\web_of_science\raw_data\savedrecs_3.xls | C4: 417 | D4: 417 | E4: 72 | F4: 25 | G4: ok

Sheet input_manifest
A1: file_name | B1: file_path | C1: suffix | D1: size_bytes | E1: modified_time_iso | F1: sha256
A2: savedrecs_1.xls | B2: C:\Users\Luís Pinto Coelho\Desktop\Dissertação\StudyScreening_Meta-Analysis\data\web_of_science\raw_data\savedrecs_1.xls | C2: .xls | D2: 3935744 | E2: 2025-11-07T20:00:34 | F2: 7eb144d274468473421e6e50c00bad5c7bfdee340b9a449acb83ba7a1a5b1cc3
A3: savedrecs_2.xls | B3: C:\Users\Luís Pinto Coelho\Desktop\Dissertação\StudyScreening_Meta-Analysis\data\web_of_science\raw_data\savedrecs_2.xls | C3: .xls | D3: 4025344 | E3: 2025-11-07T20:00:58 | F3: 38d21a0d8d853ac52ece49015ddb184cd9a47805a79dba5d16225e9f73427313
A4: savedrecs_3.xls | B4: C:\Users\Luís Pinto Coelho\Desktop\Dissertação\StudyScreening_Meta-Analysis\data\web_of_science\raw_data\savedrecs_3.xls | C4: .xls | D4: 1800192 | E4: 2025-11-07T20:01:34 | F4: 9ec980e22522d28fe3398a1d6a968b28613fae7b29042b271d37955b4aca9cab

Sheet screening_report
A1: Initial Screening report
A3: Resumo geral
A4: Total de registos | B4: 2417
A5: Classificados | B5: 2417
A6: Por classificar | B6: 0
A7: Included (Label = 1) | B7: 994
A8: Excluded (Label = 0) | B8: 1423
A9: Included (%) | B9: 0.41125362
A10: Excluded (%) | B10: 0.58874638
A12: Distribuição por critério (excluídos)
A13: Critério | B13: N
A14: 1 – Estudo empírico | B14: 350
A15: 2 – Incide sobre trigo | B15: 634
A16: 3 – Stress térmico | B16: 386
A17: 4 – Condição de controlo | B17: 1
A18: 5 – Rendimento ou qualidade do grão | B18: 52
A20: Razões de exclusão — Ordem descdente
A21: Reason to Exclude | B21: N
A22: 2 – Incide sobre trigo | B22: 634
A23: 3 – Stress térmico | B23: 386
A24: 1 – Estudo empírico | B24: 350
A25: 5 – Rendimento ou qualidade do grão | B25: 52
A26: 4 – Condição de controlo | B26: 1

Sheet wos_full_text
A1: record_id | B1: source_record_id | C1: master_id | D1: source | E1: source_priority | F1: run_id | G1: source_path | H1: source_row_index | I1: date_imported | J1: Authors | K1: Publication Year | L1: Title | M1: Abstract | N1: Author Keywords | O1: Source Title | P1: Volume | Q1: Issue | R1: Begin Page | S1: End Page | T1: Article Number | U1: E-mail Address | V1: DOI | W1: DOI Link | X1: pdf_downloaded | Y1: pdf_download_status | Z1: pdf_file_name | AA1: pdf_source_url | AB1: pdf_local_path | AC1: pdf_http_status | AD1: pdf_checked_at | AE1: Label | AF1: Reason to Exclude | AG1: Comment
A2: 3 | B2: WOS_savedrecs_1_r000005 | D2: WoS | E2: 1 | F2: 2026-02-26_005404 | G2: C:\Users\Luís Pinto Coelho\Desktop\Dissertação\StudyScreening_Meta-Analysis\data\web_of_science\raw_data\savedrecs_1.xls | H2: 5 | I2: 2026-02-26 | J2: Choudhary, M; Yan, GJ; Siddique, KHM; Cowling, WA | K2: 2022 | L2: Heat Stress during Meiosis Has Lasting Impacts on Plant Growth and Reproduction in Wheat (Triticum aestivum L.) | M2: Meiosis is the least explored stage for thermotolerance in wheat. We evaluated the impact of 5 d of moderate transient daily heat stress during meiosis in the main stem spike on physiological and grain yield traits in 30 diverse wheat cultivars which vary widely in heat tolerance and sensitivity. We found that a moderate heat stress event during meiosis in the main stem spike had lasting impacts on plant growth and reproduction in heat-sensitive, but not heat-tolerant, wheat cultivars. Heat-tolerant cultivars maintained grain yield, grain number and individual grain weight in the main stem spike and also total plant grain yield and biomass in the heat stress treatment relative to the control. Heat-sensitive cultivars responded to heat stress by producing fewer and smaller grains per spikelet on the main stem, fewer tillers, lower biomass and lower total plant grain yield in the high temperature treatment relative to the control. Heat-sensitive cultivars produced higher flag leaf chlorophyll content in the high temperature treatment relative to the control than heat-tolerant cultivars during the first 3 d of heat treatment. There was small reduction in pollen viability from 98% to 96% following heat stress during meiosis which was unrelated to heat tolerance or sensitivity. Moderate transient heat stress during meiosis did not greatly reduce the production of viable male gametes, but had long-lasting negative impacts on fertilization and subsequent seed production in heat-sensitive cultivars. | N2: wheat (Triticum aestivum); heat stress tolerance; meiosis; grain number; grain weight | O2: AGRONOMY-BASEL | P2: 12 | Q2: 5 | T2: 987 | U2: mukesh.choudhary@research.uwa.edu.au; guijun.yan@uwa.edu.au; kadambot.siddique@uwa.edu.au; wallace.cowling@uwa.edu.au | V2: 10.3390/agronomy12050987 | W2: https://doi.org/10.3390/agronomy12050987 | X2: 0 | Y2: paywalled | Z2: 3__Heat_Stress_during_Meiosis_Has_Lasting_Impacts_on_Plant_Growth_and_Reproduction_in_Wheat_(Triticum_aestivum_L.).pdf | AA2: https://www.mdpi.com/2073-4395/12/5/987 | AC2: 403 | AD2: 2026-03-15 11:24:28 | AE2: =IFERROR(IF(ISBLANK(INDEX(wos_screening_view_full_text!$O:$O, MATCH($A2, wos_screening_view_full_text!$B:$B, 0))), "", INDEX(wos_screening_view_full_text!$O:$O, MATCH($A2, wos_screening_view_full_text!$B:$B, 0))), "") | AF2: =IFERROR(IF(ISBLANK(INDEX(wos_screening_view_full_text!$P:$P, MATCH($A2, wos_screening_view_full_text!$B:$B, 0))), "", INDEX(wos_screening_view_full_text!$P:$P, MATCH($A2, wos_screening_view_full_text!$B:$B, 0))), "") | AG2: =IFERROR(IF(ISBLANK(INDEX(wos_screening_view_full_text!$Q:$Q, MATCH($A2, wos_screening_view_full_text!$B:$B, 0))), "", INDEX(wos_screening_view_full_text!$Q:$Q, MATCH($A2, wos_screening_view_full_text!$B:$B, 0))), "")
A3: 6 | B3: WOS_savedrecs_1_r000011 | D3: WoS | E3: 1 | F3: 2026-02-26_005404 | G3: C:\Users\Luís Pinto Coelho\Desktop\Dissertação\StudyScreening_Meta-Analysis\data\web_of_science\raw_data\savedrecs_1.xls | H3: 11 | I3: 2026-02-26 | J3: Corrêa, AAP; da Silva, FM; Moresco, ER; Cristeli, DS; Souza, JD; Unêda-Trevisoli, SH | K3: 2025 | L3: Multivariate approach for identifying wheat Triticum aestivum L. tolerant to heat and drought stress | M3: Breeding wheat for production in the Brazilian Cerrado region should aim at developing productive genotypes adapted to heat and drought conditions; therefore, this study evaluated the tolerance of wheat cultivars to heat/thermal and drought stress. To meet this objective, 30 wheat cultivars were cultivated in 3 greenhouse environments, namely control, drought, and heat, applying stress from the booting stage to the end of anthesis. The following parameters were evaluated: cycle, plant height, spike number per plant, spike length, spike weight, spikelet number per spike, percentage of fertile spikelets, number of grains per spike, and grain weight per spike. Principal component analysis and cluster analysis were performed by the Ward and K-means methods. Principal component analysis showed that the correlations between the productivity traits and the principal components were more affected by drought than by the control and heat environments. The cluster analyses formed five clusters for the control and heat environments and seven clusters for the drought environment. Grain productivity was highlighted in the heat environment for 'BRS 210', 'BR18 Terena', 'IPR Catuara TM', 'CD 154', 'BR 220', 'MGS Alian & ccedil;a', 'IAC 350', 'IAC Tucunar & eacute;', 'BR 24', 'IAC 5 Maringa', 'UFVT1 Pioneiro', and 'CD 151 4' with a positive relationship in principal component analysis. Considering spikelet number per spike in the drought environment, cultivars 'BRS 208', 'IAC 350', 'Supera', 'BRS 210', 'IPR 85', 'IPR Catuara TM', 'Anahuac 73', 'BR 24', 'IAC 5 Maringa', and 'UFVT1 Pioneiro' were highlighted. In the drought environment, most of the productivity-related traits exhibited components with negative relationships among cultivars and the evaluated traits, confirming their response to the induced stress. | N3: Triticum aestivum; thermal stress; water stress; Cerrado; genotype x environment interactions; Python | O3: ACTA SCIENTIARUM-AGRONOMY | P3: 47 | T3: e70982 | U3: jardel.souza@unesp.br | V3: 10.4025/actasciagron.v47i1.70982 | W3: https://doi.org/10.4025/actasciagron.v47i1.70982 | X3: 1 | Y3: downloaded | Z3: 6__Multivariate_approach_for_identifying_wheat_Triticum_aestivum_L._tolerant_to_heat_and_drought_stress.pdf | AA3: https://periodicos.uem.br/ojs/index.php/ActaSciAgron/article/download/70982/751375159540 | AB3: pdf_files/6__Multivariate_approach_for_identifying_wheat_Triticum_aestivum_L._tolerant_to_heat_and_drought_stress.pdf | AC3: 200 | AD3: 2026-03-15 11:24:33 | AE3: =IFERROR(IF(ISBLANK(INDEX(wos_screening_view_full_text!$O:$O, MATCH($A3, wos_screening_view_full_text!$B:$B, 0))), "", INDEX(wos_screening_view_full_text!$O:$O, MATCH($A3, wos_screening_view_full_text!$B:$B, 0))), "") | AF3: =IFERROR(IF(ISBLANK(INDEX(wos_screening_view_full_text!$P:$P, MATCH($A3, wos_screening_view_full_text!$B:$B, 0))), "", INDEX(wos_screening_view_full_text!$P:$P, MATCH($A3, wos_screening_view_full_text!$B:$B, 0))), "") | AG3: =IFERROR(IF(ISBLANK(INDEX(wos_screening_view_full_text!$Q:$Q, MATCH($A3, wos_screening_view_full_text!$B:$B, 0))), "", INDEX(wos_screening_view_full_text!$Q:$Q, MATCH($A3, wos_screening_view_full_text!$B:$B, 0))), "")
A4: 7 | B4: WOS_savedrecs_1_r000012 | D4: WoS | E4: 1 | F4: 2026-02-26_005404 | G4: C:\Users\Luís Pinto Coelho\Desktop\Dissertação\StudyScreening_Meta-Analysis\data\web_of_science\raw_data\savedrecs_1.xls | H4: 12 | I4: 2026-02-26 | J4: Mahdavi, S; Arzani, A; Maibody, SAMM; Kadivar, M | K4: 2022 | L4: Grain and flour quality of wheat genotypes grown under heat stress | M4: Heat stress during the grain-filling period is the main abiotic stress factor limiting grain yield and quality in wheat (Triticum aestivum L.). In this study, 64 wheat genotypes were exposed to heat stress during reproduction caused by delayed sowing in two growing seasons. Grain yield, 1000 grain weight (GW), grain hardness (GH), and grain-quality related traits were investigated. Heat stress caused a significant decrease in GW through reducing starch content (SC) and a non-compensating rise in protein content (PC), and thereby resulted in lower yield. In addition, significant increases in flour water absorption (WA), Zeleny sedimentation volume (ZT), ash content (AC), lipid content (LC), loaf volume (LV), wet gluten content (WG), dry gluten content (DG), gluten index (GI), and amylopectin content (APC) were found following heat stress. In contrast, decreases in grain moisture content (MC) and amylose content (AMC) induced by heat stress were observed. The heat-tolerant genotypes were superior in grain yield, GW, SC, AMC, and MC. While the sensitive genotypes contained higher PC, LV, GI and AMP. A group of wheat genotypes characterized with a higher yield, AMC, GW, and SC as well as lower PC, WA, GH, ZT, and LV; and was found to be the most heat tolerant by principal component analysis. Lighter weight and smaller grains produce a smaller starchy endosperm with lower quality (less amylose) and higher grain protein content in heat stress compared to normal conditions. Heat stress caused by delayed sowing improves some of the baking-quality related traits. (c) 2022 The Authors. Published by Elsevier B.V. on behalf of King Saud University. This is an open access article under the CC BY-NC-ND license (http://creativecommons.org/licenses/by-nc-nd/4.0/). | N4: Wheat; Global warming; Flour quality; Thermal stress | O4: SAUDI JOURNAL OF BIOLOGICAL SCIENCES | P4: 29 | Q4: 10 | T4: 103417 | U4: soraya.mahdavi@ag.iut.ac.ir; a_arzani@iut.ac.ir; maibody@iut.ac.ir; kadivar@iut.ac.ir | V4: 10.1016/j.sjbs.2022.103417 | W4: https://doi.org/10.1016/j.sjbs.2022.103417 | X4: 0 | Y4: manual_check | Z4: 7__Grain_and_flour_quality_of_wheat_genotypes_grown_under_heat_stress.pdf | AA4: https://linkinghub.elsevier.com/retrieve/pii/S1319562X22003333 | AC4: 200 | AD4: 2026-03-15 11:24:35 | AE4: =IFERROR(IF(ISBLANK(INDEX(wos_screening_view_full_text!$O:$O, MATCH($A4, wos_screening_view_full_text!$B:$B, 0))), "", INDEX(wos_screening_view_full_text!$O:$O, MATCH($A4, wos_screening_view_full_text!$B:$B, 0))), "") | AF4: =IFERROR(IF(ISBLANK(INDEX(wos_screening_view_full_text!$P:$P, MATCH($A4, wos_screening_view_full_text!$B:$B, 0))), "", INDEX(wos_screening_view_full_text!$P:$P, MATCH($A4, wos_screening_view_full_text!$B:$B, 0))), "") | AG4: =IFERROR(IF(ISBLANK(INDEX(wos_screening_view_full_text!$Q:$Q, MATCH($A4, wos_screening_view_full_text!$B:$B, 0))), "", INDEX(wos_screening_view_full_text!$Q:$Q, MATCH($A4, wos_screening_view_full_text!$B:$B, 0))), "")
A5: 8 | B5: WOS_savedrecs_1_r000013 | D5: WoS | E5: 1 | F5: 2026-02-26_005404 | G5: C:\Users\Luís Pinto Coelho\Desktop\Dissertação\StudyScreening_Meta-Analysis\data\web_of_science\raw_data\savedrecs_1.xls | H5: 13 | I5: 2026-02-26 | J5: Mohanty, N | K5: 2003 | L5: Photosynthetic characteristics and enzymatic antioxidant capacity of flag leaf and the grain yield in two cultivars of Triticum aestivum (L.) exposed to warmer growth conditions | M5: Using late sowing practice, the reproductive growth (anthesis and kernel filling) phase of two wheat cultivars, HD1553 and HD2307 was exposed to warmer growth conditions, and the effect on grain yield was examined. The grain weight declined in late-sown plants of both cultivars, but the number of grains per spike decreased drastically in HD1553 plants. In this cultivar exposure to warmer temperature during reproductive phase led to 67% fewer grains per spike. Examination of photosynthetic and enzymatic antioxidant capacity in flag leaves of late-sown plants revealed a marked reduction in chlorophyll and carotenoid pigmentation in addition to a decline in the activity of H2O2 metabolising enzymes in HD1553 cultivar. The photo-oxidative pigment loss due to warmer growth conditions in late-shown HD1553 plants could lead to a reduction in flag leaf photosynthesis and contribute to poor grain yield. | N5: wheat cultivars; heat-tolerance of flag leaf functions; H2O2. metabolising enzymes; flag leaf senescence; reproductive growth and grain yield | O5: JOURNAL OF PLANT PHYSIOLOGY | P5: 160 | Q5: 1 | R5: 71 | S5: 74 | V5: 10.1078/0176-1617-00847 | W5: https://doi.org/10.1078/0176-1617-00847 | X5: 0 | Y5: manual_check | Z5: 8__Photosynthetic_characteristics_and_enzymatic_antioxidant_capacity_of_flag_leaf_and_the_grain_yield_in_two_cultivars_of_Triticum_aestivum_(L..pdf | AA5: https://linkinghub.elsevier.com/retrieve/pii/S017616170470379X | AC5: 200 | AD5: 2026-03-15 11:24:36 | AE5: =IFERROR(IF(ISBLANK(INDEX(wos_screening_view_full_text!$O:$O, MATCH($A5, wos_screening_view_full_text!$B:$B, 0))), "", INDEX(wos_screening_view_full_text!$O:$O, MATCH($A5, wos_screening_view_full_text!$B:$B, 0))), "") | AF5: =IFERROR(IF(ISBLANK(INDEX(wos_screening_view_full_text!$P:$P, MATCH($A5, wos_screening_view_full_text!$B:$B, 0))), "", INDEX(wos_screening_view_full_text!$P:$P, MATCH($A5, wos_screening_view_full_text!$B:$B, 0))), "") | AG5: =IFERROR(IF(ISBLANK(INDEX(wos_screening_view_full_text!$Q:$Q, MATCH($A5, wos_screening_view_full_text!$B:$B, 0))), "", INDEX(wos_screening_view_full_text!$Q:$Q, MATCH($A5, wos_screening_view_full_text!$B:$B, 0))), "")
A6: 11 | B6: WOS_savedrecs_1_r000019 | D6: WoS | E6: 1 | F6: 2026-02-26_005404 | G6: C:\Users\Luís Pinto Coelho\Desktop\Dissertação\StudyScreening_Meta-Analysis\data\web_of_science\raw_data\savedrecs_1.xls | H6: 19 | I6: 2026-02-26 | J6: Cao, XY; Mondal, S; Cheng, DG; Wang, CG; Liu, AF; Song, JM; Li, HS; Zhao, ZD; Liu, JJ | K6: 2015 | L6: Evaluation of agronomic and physiological traits associated with high temperature stress tolerance in the winter wheat cultivars | M6: Post-anthesis high temperature stress is a major concern for the winter wheat producing areas in east China, especially in Shandong province. Fourteen agronomic and physiological traits were studied in 58 Chinese wheat accessions under high-temperature conditions in 2012 and 2013. High temperature stress led to reduction in grain yield and other yield component traits. Significant variations were observed for grain yield per plant (GYPP), grain weight per spike (GWS), thousand kernel weight (TKW), grain number of the main-spike, spikelet number and biological yield per plant. Among the physiological traits measured, chlorophyll content and normalized difference vegetation index showed significant variation under high temperature stress. The results indicate that heat susceptibility index estimated for TKW, GYPP, GWS and flag leaf senescence scale (FLSS) could be used as selection criteria for identifying heat tolerant genotypes for the Shandong province. The results also suggest that FLSS is a good, quick visual indicator of staygreen for field selection for heat tolerance. After harvest, TKW can be measured as final indicator of heat tolerance. The varieties Gaoyou 9415, Hemai 13, Jimai 22, Kexin 9, Shannong 8355, Taishan 23, Yannong 5286 and Zimai 7 were heat tolerant and potential germplasm for heat tolerance breeding in Shandong province and other parts of China. The results could be useful for breeding climate resilient varieties for China or other countries in the world suffering high temperature stresses during grain filling period. | N6: Winter bread wheat; High-temperature; Agronomic traits; Physiological traits; Heat tolerance | O6: ACTA PHYSIOLOGIAE PLANTARUM | P6: 37 | Q6: 4 | T6: 90 | U6: cxytvs@163.com; wheat9561@sina.com | V6: 10.1007/s11738-015-1835-6 | W6: https://doi.org/10.1007/s11738-015-1835-6 | X6: 1 | Y6: downloaded | Z6: 11__Evaluation_of_agronomic_and_physiological_traits_associated_with_high_temperature_stress_tolerance_in_the_winter_wheat_cultivars.pdf | AA6: https://link.springer.com/content/pdf/10.1007/s11738-015-1835-6.pdf | AB6: pdf_files/11__Evaluation_of_agronomic_and_physiological_traits_associated_with_high_temperature_stress_tolerance_in_the_winter_wheat_cultivars.pdf | AC6: 200 | AD6: 2026-03-15 11:24:40 | AE6: =IFERROR(IF(ISBLANK(INDEX(wos_screening_view_full_text!$O:$O, MATCH($A6, wos_screening_view_full_text!$B:$B, 0))), "", INDEX(wos_screening_view_full_text!$O:$O, MATCH($A6, wos_screening_view_full_text!$B:$B, 0))), "") | AF6: =IFERROR(IF(ISBLANK(INDEX(wos_screening_view_full_text!$P:$P, MATCH($A6, wos_screening_view_full_text!$B:$B, 0))), "", INDEX(wos_screening_view_full_text!$P:$P, MATCH($A6, wos_screening_view_full_text!$B:$B, 0))), "") | AG6: =IFERROR(IF(ISBLANK(INDEX(wos_screening_view_full_text!$Q:$Q, MATCH($A6, wos_screening_view_full_text!$B:$B, 0))), "", INDEX(wos_screening_view_full_text!$Q:$Q, MATCH($A6, wos_screening_view_full_text!$B:$B, 0))), "")
A7: 13 | B7: WOS_savedrecs_1_r000023 | D7: WoS | E7: 1 | F7: 2026-02-26_005404 | G7: C:\Users\Luís Pinto Coelho\Desktop\Dissertação\StudyScreening_Meta-Analysis\data\web_of_science\raw_data\savedrecs_1.xls | H7: 23 | I7: 2026-02-26 | J7: Mirosavljevic, M; Mikic, S; Spika, AK; Zupunski, V; Zhou, R; Abdelhakim, L; Ottosen, CO | K7: 2021 | L7: The effect of heat stress on some main spike traits in 12 wheat cultivars at anthesis and mid-grain filling stage | M7: High temperature decreases winter wheat grain yield by reducing the grain number and grain weight. The effect of heat stress on spike grain distribution and weight of individual grains within spike and spikelets was less studied. Our aim is to identify influence of high temperatures during different phenological stages on spike grain distribution and weight and to explore genotypic variation of the studied wheat cultivars. Within this study, controlled experiment was conducted with 12 different winter wheat cultivars under heat stress at anthesis and mid-grain filling stage. The results showed that spike grain weight, thousand-grain weight and grain number per spike decreased moderately in treatments with individual heat stress at anthesis and mid-grain filling period, respectively, which decreased severely in the multiple heat stressed plants at both stages compared with the control treatment. Heat stress decreased number of spikelets with grains. Grain weight at the G1, G2 and G3 positions had positive relationship with spike grain weight. Among the studied Serbian wheat cultivars Suboticanka and Renesansa were identified as the most heat tolerant and sensitive, respectively. Heat tolerance of the studied cultivars should be based on the cultivar capacity to retain higher grain weight, and to maintain production of distal spikelet grains. | N7: cereal; drought; extreme heat; flowering; global warming; Triticum aestivum L. | O7: PLANT SOIL AND ENVIRONMENT | P7: 67 | Q7: 2 | R7: 71 | S7: 76 | U7: milan.mirosavljevic@nsseme.com | V7: 10.17221/457/2020-pse | W7: https://doi.org/10.17221/457/2020-pse | X7: 1 | Y7: downloaded | Z7: 13__The_effect_of_heat_stress_on_some_main_spike_traits_in_12_wheat_cultivars_at_anthesis_and_mid-grain_filling_stage.pdf | AA7: http://pse.agriculturejournals.cz/pdfs/pse/2021/02/02.pdf | AB7: pdf_files/13__The_effect_of_heat_stress_on_some_main_spike_traits_in_12_wheat_cultivars_at_anthesis_and_mid-grain_filling_stage.pdf | AC7: 200 | AD7: 2026-03-15 11:24:43 | AE7: =IFERROR(IF(ISBLANK(INDEX(wos_screening_view_full_text!$O:$O, MATCH($A7, wos_screening_view_full_text!$B:$B, 0))), "", INDEX(wos_screening_view_full_text!$O:$O, MATCH($A7, wos_screening_view_full_text!$B:$B, 0))), "") | AF7: =IFERROR(IF(ISBLANK(INDEX(wos_screening_view_full_text!$P:$P, MATCH($A7, wos_screening_view_full_text!$B:$B, 0))), "", INDEX(wos_screening_view_full_text!$P:$P, MATCH($A7, wos_screening_view_full_text!$B:$B, 0))), "") | AG7: =IFERROR(IF(ISBLANK(INDEX(wos_screening_view_full_text!$Q:$Q, MATCH($A7, wos_screening_view_full_text!$B:$B, 0))), "", INDEX(wos_screening_view_full_text!$Q:$Q, MATCH($A7, wos_screening_view_full_text!$B:$B, 0))), "")
A8: 15 | B8: WOS_savedrecs_1_r000026 | D8: WoS | E8: 1 | F8: 2026-02-26_005404 | G8: C:\Users\Luís Pinto Coelho\Desktop\Dissertação\StudyScreening_Meta-Analysis\data\web_of_science\raw_data\savedrecs_1.xls | H8: 26 | I8: 2026-02-26 | J8: Vedi, A; Raghuvanshi, D; Tripathi, A; Pandey, GC | K8: 2024 | L8: Characterization of Traits Associated with Grain Yield Under Terminal Heat Stress in Bread Wheat (Triticum aestivum L.) on the Basis of Heat Susceptibility Index | M8: High temperature affects various morpho-physiological and agronomical traits in wheat crops. High-temperature stress can cause poor seed growth, reduction in grain filling duration and grain number, root growth and yield reduction. For the identification of heat tolerant genotype, fifteen wheat cultivars were evaluated under timely and late sown conditions based on grain yield in 2018-2019 crop seasons by precise phenotyping approach for this study. Heat susceptibility index (HSI) value recorded for grain filling duration and canopy temperature ranged from 0.57 to 1.35 with a mean value of 1.00 and 0.58-1.29 with a mean value of 1.005, respectively. Grain no./spike and grain weight/spike HSI values ranged from 0.28 to 1.60 (mean value 1.004) and 0.81-1.21 (mean value 0.99), respectively, with thousand-grain weight values ranging from 0.64 to 1.18 (mean value 0.98). Two (WH730 and HUW468) genotypes showed tolerance to heat in all traits, and five genotypes (K7903, RAJ4079, Hindi62, PBW723 and HD3086) showed tolerance in either one trait or none depicting them as sensitive to high temperature. | N8: Heat stress; Heat susceptibility index; Grain yield; Wheat | O8: NATIONAL ACADEMY SCIENCE LETTERS-INDIA | P8: 47 | Q8: 2 | R8: 173 | S8: 175 | U8: aarushivedi@gmail.com | V8: 10.1007/s40009-023-01331-x | W8: https://doi.org/10.1007/s40009-023-01331-x | X8: 1 | Y8: downloaded | Z8: 15__Characterization_of_Traits_Associated_with_Grain_Yield_Under_Terminal_Heat_Stress_in_Bread_Wheat_(Triticum_aestivum_L.)_on_the_Basis_of_Heat.pdf | AA8: https://link.springer.com/content/pdf/10.1007/s40009-023-01331-x.pdf | AB8: pdf_files/15__Characterization_of_Traits_Associated_with_Grain_Yield_Under_Terminal_Heat_Stress_in_Bread_Wheat_(Triticum_aestivum_L.)_on_the_Basis_of_Heat.pdf | AC8: 200 | AD8: 2026-03-15 11:24:46 | AE8: =IFERROR(IF(ISBLANK(INDEX(wos_screening_view_full_text!$O:$O, MATCH($A8, wos_screening_view_full_text!$B:$B, 0))), "", INDEX(wos_screening_view_full_text!$O:$O, MATCH($A8, wos_screening_view_full_text!$B:$B, 0))), "") | AF8: =IFERROR(IF(ISBLANK(INDEX(wos_screening_view_full_text!$P:$P, MATCH($A8, wos_screening_view_full_text!$B:$B, 0))), "", INDEX(wos_screening_view_full_text!$P:$P, MATCH($A8, wos_screening_view_full_text!$B:$B, 0))), "") | AG8: =IFERROR(IF(ISBLANK(INDEX(wos_screening_view_full_text!$Q:$Q, MATCH($A8, wos_screening_view_full_text!$B:$B, 0))), "", INDEX(wos_screening_view_full_text!$Q:$Q, MATCH($A8, wos_screening_view_full_text!$B:$B, 0))), "")
A9: 17 | B9: WOS_savedrecs_1_r000028 | D9: WoS | E9: 1 | F9: 2026-02-26_005404 | G9: C:\Users\Luís Pinto Coelho\Desktop\Dissertação\StudyScreening_Meta-Analysis\data\web_of_science\raw_data\savedrecs_1.xls | H9: 28 | I9: 2026-02-26 | J9: SHPILER, L; BLUM, A | K9: 1990 | L9: HEAT TOLERANCE FOR YIELD AND ITS COMPONENTS IN DIFFERENT WHEAT CULTIVARS | M9: Twenty one diverse, standard and experimental cultivars of common spring wheat (Triticum aestivum L.) were tested for the effect of heat stress on phenology, yield and its components by growing the materials for 2 years under full irrigation during the hot summer (offseason), and the cool winter (normal) conditions. Heat tolerance was estimated for each variable by the 'heat susceptibility index' (S) which scales the reduction in cultivar performance from cool to hot conditions relative to the respective mean reduction over all cultivars. Genotypes differed significantly in S for yield and its components. The ranking of cultivars in S over the 2 years was consistent for yield, kernels per spike and kernel weight, but not for spike number. Of the three yield components, the greatest genotypic variation in S was expressed for kernels per spike. However, S for yield could not be simply attributed to S in a unique component across all cultivars. On the other hand, a general linear model regression of summer yield on its components revealed that the most important yield component affecting yield variation among cultivars under heat stress was kernel number per spike. Kernel number per spike was positively associated across cultivars with longer duration and greater stability of thermal time requirement from emergence to 'double ridge'. It is therefore concluded that kernel number per spike under heat stress is a reasonable estimate of heat tolerance in yield of wheat and that this tolerance is operative already during the first 2 to 3 weeks of growth. | N9: TRITICUM-AESTIVUM; WHEAT; HEAT TOLERANCE; PHENOLOGY; YIELD COMPONENTS; SELECTION | O9: EUPHYTICA | P9: 51 | Q9: 3 | R9: 257 | S9: 263 | V9: 10.1007/bf00039727 | W9: https://doi.org/10.1007/bf00039727 | X9: 1 | Y9: downloaded | Z9: 17__HEAT_TOLERANCE_FOR_YIELD_AND_ITS_COMPONENTS_IN_DIFFERENT_WHEAT_CULTIVARS.pdf | AA9: https://link.springer.com/content/pdf/10.1007/BF00039727.pdf | AB9: pdf_files/17__HEAT_TOLERANCE_FOR_YIELD_AND_ITS_COMPONENTS_IN_DIFFERENT_WHEAT_CULTIVARS.pdf | AC9: 200 | AD9: 2026-03-15 11:24:48 | AE9: =IFERROR(IF(ISBLANK(INDEX(wos_screening_view_full_text!$O:$O, MATCH($A9, wos_screening_view_full_text!$B:$B, 0))), "", INDEX(wos_screening_view_full_text!$O:$O, MATCH($A9, wos_screening_view_full_text!$B:$B, 0))), "") | AF9: =IFERROR(IF(ISBLANK(INDEX(wos_screening_view_full_text!$P:$P, MATCH($A9, wos_screening_view_full_text!$B:$B, 0))), "", INDEX(wos_screening_view_full_text!$P:$P, MATCH($A9, wos_screening_view_full_text!$B:$B, 0))), "") | AG9: =IFERROR(IF(ISBLANK(INDEX(wos_screening_view_full_text!$Q:$Q, MATCH($A9, wos_screening_view_full_text!$B:$B, 0))), "", INDEX(wos_screening_view_full_text!$Q:$Q, MATCH($A9, wos_screening_view_full_text!$B:$B, 0))), "")
A10: 18 | B10: WOS_savedrecs_1_r000029 | D10: WoS | E10: 1 | F10: 2026-02-26_005404 | G10: C:\Users\Luís Pinto Coelho\Desktop\Dissertação\StudyScreening_Meta-Analysis\data\web_of_science\raw_data\savedrecs_1.xls | H10: 29 | I10: 2026-02-26 | J10: Fu, JM; Bowden, RL; Jagadish, SVK; Prasad, PVV | K10: 2023 | L10: Genetic variation for terminal heat stress tolerance in winter wheat | M10: In many regions worldwide wheat (Triticum aestivum L.) plants experience terminal high temperature stress during the grain filling stage, which is a leading cause for single seed weight decrease and consequently for grain yield reduction. An approach to mitigate high temperature damage is to develop tolerant cultivars using the conventional breeding approach which involves identifying tolerant lines and then incorporating the tolerant traits in commercial varieties. In this study, we evaluated the terminal heat stress tolerance of 304 diverse elite winter wheat lines from wheat breeding programs in the US, Australia, and Serbia in controlled environmental conditions. Chlorophyll content and yield traits were measured and calculated as the percentage of non-stress control. The results showed that there was significant genetic variation for chlorophyll retention and seed weight under heat stress conditions. The positive correlation between the percent of chlorophyll content and the percent of single seed weight was significant. Two possible mechanisms of heat tolerance during grain filling were proposed. One represented by wheat line OK05723W might be mainly through the current photosynthesis since the high percentage of single seed weight was accompanied with high percentages of chlorophyll content and high shoot dry weight, and the other represented by wheat Line TX04M410164 might be mainly through the relocation of reserves since the high percentage of single seed weight was accompanied with low percentages of chlorophyll content and low shoot dry weight under heat stress. The tolerant genotypes identified in this study should be useful for breeding programs after further validation. | N10: heat stress; wheat; chlorophyll; yield components; controlled environment | O10: FRONTIERS IN PLANT SCIENCE | P10: 14 | T10: 1132108 | U10: jianming@ksu.edu | V10: 10.3389/fpls.2023.1132108 | W10: https://doi.org/10.3389/fpls.2023.1132108 | X10: 1 | Y10: downloaded | Z10: 18__Genetic_variation_for_terminal_heat_stress_tolerance_in_winter_wheat.pdf | AA10: https://public-pages-files-2025.frontiersin.org/journals/plant-science/articles/10.3389/fpls.2023.1132108/pdf | AB10: pdf_files/18__Genetic_variation_for_terminal_heat_stress_tolerance_in_winter_wheat.pdf | AC10: 200 | AD10: 2026-03-15 11:24:52 | AE10: =IFERROR(IF(ISBLANK(INDEX(wos_screening_view_full_text!$O:$O, MATCH($A10, wos_screening_view_full_text!$B:$B, 0))), "", INDEX(wos_screening_view_full_text!$O:$O, MATCH($A10, wos_screening_view_full_text!$B:$B, 0))), "") | AF10: =IFERROR(IF(ISBLANK(INDEX(wos_screening_view_full_text!$P:$P, MATCH($A10, wos_screening_view_full_text!$B:$B, 0))), "", INDEX(wos_screening_view_full_text!$P:$P, MATCH($A10, wos_screening_view_full_text!$B:$B, 0))), "") | AG10: =IFERROR(IF(ISBLANK(INDEX(wos_screening_view_full_text!$Q:$Q, MATCH($A10, wos_screening_view_full_text!$B:$B, 0))), "", INDEX(wos_screening_view_full_text!$Q:$Q, MATCH($A10, wos_screening_view_full_text!$B:$B, 0))), "")
A11: 19 | B11: WOS_savedrecs_1_r000030 | D11: WoS | E11: 1 | F11: 2026-02-26_005404 | G11: C:\Users\Luís Pinto Coelho\Desktop\Dissertação\StudyScreening_Meta-Analysis\data\web_of_science\raw_data\savedrecs_1.xls | H11: 30 | I11: 2026-02-26 | J11: Sharma, RC; Tiwary, AK; Ortiz-Ferrara, G | K11: 2008 | L11: Reduction in kernel weight as a potential indirect selection criterion for wheat grain yield under terminal heat stress | M11: Heat is an important abiotic stress during wheat (Triticum aestivum L.) grain-filling in South Asia. A study was undertaken to determine effectiveness of selection for reduction in 1000-kernel weight (TKWR) under heat stress to increase grain yield. Selection was made for low and high TKWR and selected progenies were evaluated in timely and late seeded trials at two locations in Nepal in 2003. One thousand kernel weight (TKW), biomass yield, grain yield, harvest index (HI), grain-filling duration (GFD) and area under spot blotch progress curve per day (AUDPC/day) were examined. The low and high TKWR groups did not differ significantly for TKW, biomass yield, grain yield, HI, days to heading, GFD and AUDPC/day under timely seeding. However, low TKWR lines showed higher TKW, biomass yield, grain yield, HI, and GFD and lower AUDPC/day than the lines with high TKWR under late seeding. Realized heritability estimates for TKWR ranged from 0.68 to 0.85. The findings show that selection for low TKWR could be used as an indirect selection criterion to identify high grain yielding lines under terminal heat stress. | N11: grain yield; heat stress; heritability; kernel weight; seeding date; selection; Triticum aestivum; wheat | O11: PLANT BREEDING | P11: 127 | Q11: 3 | R11: 241 | S11: 248 | U11: rsharma@ecomail.com.np | V11: 10.1111/j.1439-0523.2007.01460.x | W11: https://doi.org/10.1111/j.1439-0523.2007.01460.x | X11: 0 | Y11: paywalled | Z11: 19__Reduction_in_kernel_weight_as_a_potential_indirect_selection_criterion_for_wheat_grain_yield_under_terminal_heat_stress.pdf | AA11: https://onlinelibrary.wiley.com/doi/10.1111/j.1439-0523.2007.01460.x | AC11: 403 | AD11: 2026-03-15 11:24:53 | AE11: =IFERROR(IF(ISBLANK(INDEX(wos_screening_view_full_text!$O:$O, MATCH($A11, wos_screening_view_full_text!$B:$B, 0))), "", INDEX(wos_screening_view_full_text!$O:$O, MATCH($A11, wos_screening_view_full_text!$B:$B, 0))), "") | AF11: =IFERROR(IF(ISBLANK(INDEX(wos_screening_view_full_text!$P:$P, MATCH($A11, wos_screening_view_full_text!$B:$B, 0))), "", INDEX(wos_screening_view_full_text!$P:$P, MATCH($A11, wos_screening_view_full_text!$B:$B, 0))), "") | AG11: =IFERROR(IF(ISBLANK(INDEX(wos_screening_view_full_text!$Q:$Q, MATCH($A11, wos_screening_view_full_text!$B:$B, 0))), "", INDEX(wos_screening_view_full_text!$Q:$Q, MATCH($A11, wos_screening_view_full_text!$B:$B, 0))), "")
A12: 23 | B12: WOS_savedrecs_1_r000035 | D12: WoS | E12: 1 | F12: 2026-02-26_005404 | G12: C:\Users\Luís Pinto Coelho\Desktop\Dissertação\StudyScreening_Meta-Analysis\data\web_of_science\raw_data\savedrecs_1.xls | H12: 35 | I12: 2026-02-26 | J12: Mahdavi, S; Arzani, A; Maibody, SAMM; Mehrabi, AA | K12: 2021 | L12: Photosynthetic and yield performance of wheat (Triticum aestivum L.) under sowing in hot environment | M12: Heat stress during the post-flowering and grain development stages is a key abiotic stress influencing grain yield in wheat (Triticum aestivum L.). In this study, 64 wheat genotypes, in their terminal growth stage, were subjected to two field temperatures caused by delayed sowing in two consecutive growing seasons. Results of photosynthetic gas exchange, chlorophyll fluorescence, yield attributes, and grain yield investigations were subjected to combined analysis of variance, which revealed significant differences in the 1000 grain weight (GW), grain filling duration (GFD), grain yield, gas exchange parameters, and maximum quantum efficiency PSII photochemistry (Fv/Fm) among the genotypes (G) between the normal and heat stress conditions (E) and G x E interactions. Heat stress accelerated reproductive phases and shortened GFD leading to lower GW and grain yield. Exposure to heat stress resulted in significant decreases in net CO2 assimilation rate (P-N), stomatal conductance (gs), transpiration rate (E), iWUE, WUE, Fv/Fm ratio, and yield, while it increased sub-stomatal CO2 concentration (C-i). Moreover, grain yield was found to be strongly correlated with C-i, Fv/Fm, and P-N. Path coefficient analysis and stepwise multiple regression revealed that greater improvements will be achieved in C-i and Fv/Fm by increasing yield and P-N performance when wheat is bred for tolerance to heat stress than those achieved by breeders under normal growing conditions. | N12: Global warming; Thermal stress; Photosynthesis; Chlorophyll fluorescent; Common wheat | O12: ACTA PHYSIOLOGIAE PLANTARUM | P12: 43 | Q12: 7 | T12: 106 | U12: a_arzani@iut.ac.ir | V12: 10.1007/s11738-021-03278-2 | W12: https://doi.org/10.1007/s11738-021-03278-2 | X12: 1 | Y12: downloaded | Z12: 23__Photosynthetic_and_yield_performance_of_wheat_(Triticum_aestivum_L.)_under_sowing_in_hot_environment.pdf | AA12: https://link.springer.com/content/pdf/10.1007/s11738-021-03278-2.pdf | AB12: pdf_files/23__Photosynthetic_and_yield_performance_of_wheat_(Triticum_aestivum_L.)_under_sowing_in_hot_environment.pdf | AC12: 200 | AD12: 2026-03-15 11:24:56 | AE12: =IFERROR(IF(ISBLANK(INDEX(wos_screening_view_full_text!$O:$O, MATCH($A12, wos_screening_view_full_text!$B:$B, 0))), "", INDEX(wos_screening_view_full_text!$O:$O, MATCH($A12, wos_screening_view_full_text!$B:$B, 0))), "") | AF12: =IFERROR(IF(ISBLANK(INDEX(wos_screening_view_full_text!$P:$P, MATCH($A12, wos_screening_view_full_text!$B:$B, 0))), "", INDEX(wos_screening_view_full_text!$P:$P, MATCH($A12, wos_screening_view_full_text!$B:$B, 0))), "") | AG12: =IFERROR(IF(ISBLANK(INDEX(wos_screening_view_full_text!$Q:$Q, MATCH($A12, wos_screening_view_full_text!$B:$B, 0))), "", INDEX(wos_screening_view_full_text!$Q:$Q, MATCH($A12, wos_screening_view_full_text!$B:$B, 0))), "")
A13: 24 | B13: WOS_savedrecs_1_r000036 | D13: WoS | E13: 1 | F13: 2026-02-26_005404 | G13: C:\Users\Luís Pinto Coelho\Desktop\Dissertação\StudyScreening_Meta-Analysis\data\web_of_science\raw_data\savedrecs_1.xls | H13: 36 | I13: 2026-02-26 | J13: Schmidt, J; Tricker, PJ; Eckermann, P; Kalambettu, P; Garcia, M; Fleury, D | K13: 2020 | L13: Novel Alleles for Combined Drought and Heat Stress Tolerance in Wheat | M13: Drought and heat waves commonly co-occur in many wheat-growing regions causing significant crop losses. The identification of stress associated quantitative trait loci, particularly those for yield, is problematic due to their association with plant phenology and the high genetic x environment interaction. Here we studied a panel of 315 diverse, spring type accessions of bread wheat (Triticum aestivum) in pots in a semi-controlled environment under combined drought and heat stress over 2 years. Importantly, we treated individual plants according to their flowering time. We found 134 out of the 145 identified loci for grain weight that were not associated with either plant phenology or plant height. The majority of loci uncovered here were novel, with favorable alleles widespread in Asian and African landraces providing opportunities for their incorporation into modern varieties through breeding. Using residual heterozygosity in lines from a nested association mapping population, we were able to rapidly develop near-isogenic lines for important target loci. One target locus on chromosome 6A contributed to higher grain weight, harvest index, thousand kernel weight, and grain number under drought and heat stress in field conditions consistent with allelic effects demonstrated in the genome-wide association study. | N13: genome-wide association; quantitative trait loci; near-isogenic lines; Triticum; abiotic; genetic diversity | O13: FRONTIERS IN PLANT SCIENCE | P13: 10 | T13: 1800 | U13: melissa.garcia@adelaida.edu.au | V13: 10.3389/fpls.2019.01800 | W13: https://doi.org/10.3389/fpls.2019.01800 | X13: 1 | Y13: downloaded | Z13: 24__Novel_Alleles_for_Combined_Drought_and_Heat_Stress_Tolerance_in_Wheat.pdf | AA13: https://public-pages-files-2025.frontiersin.org/journals/plant-science/articles/10.3389/fpls.2019.01800/pdf | AB13: pdf_files/24__Novel_Alleles_for_Combined_Drought_and_Heat_Stress_Tolerance_in_Wheat.pdf | AC13: 200 | AD13: 2026-03-15 11:24:59 | AE13: =IFERROR(IF(ISBLANK(INDEX(wos_screening_view_full_text!$O:$O, MATCH($A13, wos_screening_view_full_text!$B:$B, 0))), "", INDEX(wos_screening_view_full_text!$O:$O, MATCH($A13, wos_screening_view_full_text!$B:$B, 0))), "") | AF13: =IFERROR(IF(ISBLANK(INDEX(wos_screening_view_full_text!$P:$P, MATCH($A13, wos_screening_view_full_text!$B:$B, 0))), "", INDEX(wos_screening_view_full_text!$P:$P, MATCH($A13, wos_screening_view_full_text!$B:$B, 0))), "") | AG13: =IFERROR(IF(ISBLANK(INDEX(wos_screening_view_full_text!$Q:$Q, MATCH($A13, wos_screening_view_full_text!$B:$B, 0))), "", INDEX(wos_screening_view_full_text!$Q:$Q, MATCH($A13, wos_screening_view_full_text!$B:$B, 0))), "")
A14: 26 | B14: WOS_savedrecs_1_r000039 | D14: WoS | E14: 1 | F14: 2026-02-26_005404 | G14: C:\Users\Luís Pinto Coelho\Desktop\Dissertação\StudyScreening_Meta-Analysis\data\web_of_science\raw_data\savedrecs_1.xls | H14: 39 | I14: 2026-02-26 | J14: Tahir, ISA; Nakata, N; Ali, AM; Mustafa, HM; Saad, ASI; Takata, K; Ishikawa, N; Abdalla, OS | K14: 2006 | L14: Genotypic and temperature effects on wheat grain yield and quality in a hot irrigated environment | M14: High temperature influences both grain yield and end-use quality of wheat. The objectives of this study were to evaluate the performance of selected wheat genotypes under heat stress and to examine the effects of high temperatures during grain filling on grain yield and end-use quality parameters. Fifteen bread wheat genotypes in 2000/2001 and 18 eenotypes in 2002/2003 were evaluated under the optimum and late-sowing conditions of the irrigated hot environment of the Gezira Research Farm, Wad Medam, Sudan. The genotypes comprised released varieties and elite lines from the Sudanese wheat improvement programme. Data collected included grain yield, grain weight and grain end-use quality including protein content, protein composition, SDS sedimentation values (SDSS) and gluten strength as determined by mixograph analyses. High temperatures significantly decreased grain yield by decreasing grain weight. Although genotypes exhibited variation in magnitude of response, results indicated that high temperature during grain filling increased both soluble and insoluble protein contents, SDSS, mixograph peak height (MPH) and the descending slope at 2 min past peak (MDS). In contrast, mixograph peak time (MPT) and the curve width at 2 min past peak (MCW) were significantly decreased. Flour protein correlated positively with SDSS, MPH and MDS and negatively with MCW. MPT correlated negatively with MDS and positively with MCW. Results indicate that high temperature increased both soluble and insoluble protein contents, SDSS and MPH, and hence the gluten strength, but decreased flour mixing time and tolerance and hence the dough elasticity. Variation observed among genotypes suggests that grain end-use quality could be improved under high temperature conditions utilizing the available variability; however, it might require evaluation under various growing conditions. | N14: Triticum aestivum; high temperature; grain quality; late sowing; mixograph parameters | O14: PLANT BREEDING | P14: 125 | Q14: 4 | R14: 323 | S14: 330 | U14: izzatahir@yahoo.com | V14: 10.1111/j.1439-0523.2006.01236.x | W14: https://doi.org/10.1111/j.1439-0523.2006.01236.x | X14: 0 | Y14: paywalled | Z14: 26__Genotypic_and_temperature_effects_on_wheat_grain_yield_and_quality_in_a_hot_irrigated_environment.pdf | AA14: https://onlinelibrary.wiley.com/doi/10.1111/j.1439-0523.2006.01236.x | AC14: 403 | AD14: 2026-03-15 11:25:00 | AE14: =IFERROR(IF(ISBLANK(INDEX(wos_screening_view_full_text!$O:$O, MATCH($A14, wos_screening_view_full_text!$B:$B, 0))), "", INDEX(wos_screening_view_full_text!$O:$O, MATCH($A14, wos_screening_view_full_text!$B:$B, 0))), "") | AF14: =IFERROR(IF(ISBLANK(INDEX(wos_screening_view_full_text!$P:$P, MATCH($A14, wos_screening_view_full_text!$B:$B, 0))), "", INDEX(wos_screening_view_full_text!$P:$P, MATCH($A14, wos_screening_view_full_text!$B:$B, 0))), "") | AG14: =IFERROR(IF(ISBLANK(INDEX(wos_screening_view_full_text!$Q:$Q, MATCH($A14, wos_screening_view_full_text!$B:$B, 0))), "", INDEX(wos_screening_view_full_text!$Q:$Q, MATCH($A14, wos_screening_view_full_text!$B:$B, 0))), "")
A15: 27 | B15: WOS_savedrecs_1_r000040 | D15: WoS | E15: 1 | F15: 2026-02-26_005404 | G15: C:\Users\Luís Pinto Coelho\Desktop\Dissertação\StudyScreening_Meta-Analysis\data\web_of_science\raw_data\savedrecs_1.xls | H15: 40 | I15: 2026-02-26 | J15: Narayanan, S; Prasad, PVV; Fritz, AK; Boyle, DL; Gill, BS | K15: 2015 | L15: Impact of High Night-Time and High Daytime Temperature Stress on Winter Wheat | M15: High temperature is a major environmental factor that limits wheat (Triticum aestivum L.) productivity. Climate models predict greater increases in night-time temperature than in daytime temperature. The objective of this research was to compare the effects of high daytime and high night-time temperatures during anthesis on physiological (chlorophyll fluorescence, chlorophyll concentration, leaf level photosynthesis, and membrane damage), biochemical (reactive oxygen species (ROS) concentration and antioxidant capacity in leaves), growth and yield traits of wheat genotypes. Winter wheat genotypes (Ventnor and Karl 92) were grown at optimum temperatures (25/15 degrees C, maximum/minimum) until the onset of anthesis. Thereafter, plants were exposed to high night-time (HN, 25/24 degrees C), high daytime (HD, 35/15 degrees C), high daytime and night-time (HDN, 35/24 degrees C) or optimum temperatures for 7days. Compared with optimum temperature, HN, HD and HDN increased ROS concentration and membrane damage and decreased antioxidant capacity, photochemical efficiency, leaf level photosynthesis, seed set, grain number and grain yield per spike. Impact of HN and HD was similar on all traits. Greater impact on seed set, grain number and grain yield per spike was observed at HDN compared with HN and HD. These results suggest that HN and HD during anthesis cause damage of a similar magnitude to winter wheat. | N15: grain yield; high daytime and night-time temperature; high daytime temperature; high night-time temperature; photosynthesis; wheat | O15: JOURNAL OF AGRONOMY AND CROP SCIENCE | P15: 201 | Q15: 3 | R15: 206 | S15: 218 | U15: vara@ksu.edu | V15: 10.1111/jac.12101 | W15: https://doi.org/10.1111/jac.12101 | X15: 0 | Y15: paywalled | Z15: 27__Impact_of_High_Night-Time_and_High_Daytime_Temperature_Stress_on_Winter_Wheat.pdf | AA15: https://onlinelibrary.wiley.com/doi/10.1111/jac.12101 | AC15: 403 | AD15: 2026-03-15 11:25:02 | AE15: =IFERROR(IF(ISBLANK(INDEX(wos_screening_view_full_text!$O:$O, MATCH($A15, wos_screening_view_full_text!$B:$B, 0))), "", INDEX(wos_screening_view_full_text!$O:$O, MATCH($A15, wos_screening_view_full_text!$B:$B, 0))), "") | AF15: =IFERROR(IF(ISBLANK(INDEX(wos_screening_view_full_text!$P:$P, MATCH($A15, wos_screening_view_full_text!$B:$B, 0))), "", INDEX(wos_screening_view_full_text!$P:$P, MATCH($A15, wos_screening_view_full_text!$B:$B, 0))), "") | AG15: =IFERROR(IF(ISBLANK(INDEX(wos_screening_view_full_text!$Q:$Q, MATCH($A15, wos_screening_view_full_text!$B:$B, 0))), "", INDEX(wos_screening_view_full_text!$Q:$Q, MATCH($A15, wos_screening_view_full_text!$B:$B, 0))), "")
A16: 29 | B16: WOS_savedrecs_1_r000043 | D16: WoS | E16: 1 | F16: 2026-02-26_005404 | G16: C:\Users\Luís Pinto Coelho\Desktop\Dissertação\StudyScreening_Meta-Analysis\data\web_of_science\raw_data\savedrecs_1.xls | H16: 43 | I16: 2026-02-26 | J16: Zhang, XX; Högy, P; Wu, XN; Schmid, I; Wang, XL; Schulze, WX; Jiang, D; Fangmeier, A | K16: 2018 | L16: Physiological and Proteomic Evidence for the Interactive Effects of Post-Anthesis Heat Stress and Elevated CO2 on Wheat | M16: Elevated CO2 promotes leaf photosynthesis and improves crop grain yield. However, as a major anthropogenic greenhouse gas, CO2 contributes to more frequent and severe heat stress, which threatens crop productivity. The combined effects of elevated CO2 and heat stress are complex, and the underlying mechanisms are poorly understood. In the present study, the effects of elevated CO2 and high-temperature on foliar physiological traits and the proteome of spring wheat grown under two CO2 concentrations (380 and 550 mu mol mol(-1)) and two temperature conditions (ambient and post-anthesis heat stress) are examined. Elevated CO2 increases leaf photosynthetic traits, biomass, and grain yield, while heat stress depresses photosynthesis and yield. Temperature-induced impacts on chlorophyll content and grain yield are not significantly different under the two CO2 concentrations. Analysis of the leaf proteome reveals that proteins involved in photosynthesis as well as antioxidant and protein synthesis pathways are significantly downregulated-due to the combination of elevated CO2 and heat stress. Correspondingly, plants treated with elevated CO2 and heat stress exhibit decreased green leaf area, photosynthetic rate, antioxidant enzyme activities, and 1000-kernel weight. The present study demonstrates that future post-anthesis heat episodes will diminish the positive effects of elevated CO2 and negatively impact wheat production. | N16: elevated CO2; grain yield; heat stress; proteomics; wheat (Triticum aestivum L.) | O16: PROTEOMICS | P16: 18 | Q16: 23 | T16: 1800262 | U16: Petra.Hoegy@uni-hohenheim.de; jiangd@njau.edu.cn | V16: 10.1002/pmic.201800262 | W16: https://doi.org/10.1002/pmic.201800262 | X16: 0 | Y16: paywalled | Z16: 29__Physiological_and_Proteomic_Evidence_for_the_Interactive_Effects_of_Post-Anthesis_Heat_Stress_and_Elevated_CO2_on_Wheat.pdf | AA16: https://analyticalsciencejournals.onlinelibrary.wiley.com/doi/10.1002/pmic.201800262 | AC16: 403 | AD16: 2026-03-15 11:25:03 | AE16: =IFERROR(IF(ISBLANK(INDEX(wos_screening_view_full_text!$O:$O, MATCH($A16, wos_screening_view_full_text!$B:$B, 0))), "", INDEX(wos_screening_view_full_text!$O:$O, MATCH($A16, wos_screening_view_full_text!$B:$B, 0))), "") | AF16: =IFERROR(IF(ISBLANK(INDEX(wos_screening_view_full_text!$P:$P, MATCH($A16, wos_screening_view_full_text!$B:$B, 0))), "", INDEX(wos_screening_view_full_text!$P:$P, MATCH($A16, wos_screening_view_full_text!$B:$B, 0))), "") | AG16: =IFERROR(IF(ISBLANK(INDEX(wos_screening_view_full_text!$Q:$Q, MATCH($A16, wos_screening_view_full_text!$B:$B, 0))), "", INDEX(wos_screening_view_full_text!$Q:$Q, MATCH($A16, wos_screening_view_full_text!$B:$B, 0))), "")
A17: 31 | B17: WOS_savedrecs_1_r000045 | D17: WoS | E17: 1 | F17: 2026-02-26_005404 | G17: C:\Users\Luís Pinto Coelho\Desktop\Dissertação\StudyScreening_Meta-Analysis\data\web_of_science\raw_data\savedrecs_1.xls | H17: 45 | I17: 2026-02-26 | J17: Jagadeesha, YK; Navathe, S; Krishnappa, G; Ambati, D; Baviskar, V; Biradar, S; Magar, N; Mishra, CN; Mamrutha, HM; Govindan, V; Singh, GP; Singh, G | K17: 2024 | L17: Multi-Environment Analysis of Nutritional and Grain Quality Traits in Relation to Grain Yield Under Drought and Terminal Heat Stress in Bread Wheat and Durum Wheat | M17: Heat and drought are two important constraints to global wheat productivity; understanding the genotypic responses for quality parameters under harsh production conditions (drought and heat) is very important for developing nutrient-dense wheat varieties. A set of 15 modern bread wheat (Triticum aestivum L. subsp. aestivum) and durum wheat (Triticum turgidum subsp. durum) cultivars were tested in nine environments, including three different production conditions (normal, heat and drought) during 2020-21. Genotype stability performance for yield, nutrition and quality parameters is assessed using multienvironment trials through AMMI and GGE Biplot analysis. We discovered intriguing stress dynamics in grain zinc content (Zn) and grain iron content (Fe). Under heat stress, zinc concentration increases but decreases under drought stress, while iron does the opposite. Selecting zinc, starch and kernel weight under terminal heat stress can boost yield. Protein content and yield are inversely related, making it difficult for breeders to optimise both traits. G x E interactions and stability indices across all environments have found genotypes with high-yielding stable genotypes, G12 (MP1358) (42.09 ppm) and G5 (HI1544) (42.41 ppm) have high Fe content. G12 (MP1358) (14.98%) ranked highest in protein concentration. Meanwhile, for Zn content, G11 (MACS 4058) (45.23 ppm) and G15 (WH730) (42.44 ppm) were top performers across environments. G7 (HI 1636) and G12 (MP1358) stand out as a win-win genotype for their high potential and stability in yield, protein, Zn and Fe content. Our study shows the complex relationships and possible suggestions for targeted breeding programmes under heat and drought stress conditions to improve wheat grain quality and micronutrient profiles without yield loss. | N17: drought; grain quality; heat; nutritional security | O17: JOURNAL OF AGRONOMY AND CROP SCIENCE | P17: 210 | Q17: 5 | T17: e12763 | U17: yashavanthak@aripune.org; sudhir.agro123@gmail.com | V17: 10.1111/jac.12763 | W17: https://doi.org/10.1111/jac.12763 | X17: 0 | Y17: paywalled | Z17: 31__Multi-Environment_Analysis_of_Nutritional_and_Grain_Quality_Traits_in_Relation_to_Grain_Yield_Under_Drought_and_Terminal_Heat_Stress_in_Brea.pdf | AA17: https://onlinelibrary.wiley.com/doi/10.1111/jac.12763 | AC17: 403 | AD17: 2026-03-15 11:25:05 | AE17: =IFERROR(IF(ISBLANK(INDEX(wos_screening_view_full_text!$O:$O, MATCH($A17, wos_screening_view_full_text!$B:$B, 0))), "", INDEX(wos_screening_view_full_text!$O:$O, MATCH($A17, wos_screening_view_full_text!$B:$B, 0))), "") | AF17: =IFERROR(IF(ISBLANK(INDEX(wos_screening_view_full_text!$P:$P, MATCH($A17, wos_screening_view_full_text!$B:$B, 0))), "", INDEX(wos_screening_view_full_text!$P:$P, MATCH($A17, wos_screening_view_full_text!$B:$B, 0))), "") | AG17: =IFERROR(IF(ISBLANK(INDEX(wos_screening_view_full_text!$Q:$Q, MATCH($A17, wos_screening_view_full_text!$B:$B, 0))), "", INDEX(wos_screening_view_full_text!$Q:$Q, MATCH($A17, wos_screening_view_full_text!$B:$B, 0))), "")
A18: 33 | B18: WOS_savedrecs_1_r000047 | D18: WoS | E18: 1 | F18: 2026-02-26_005404 | G18: C:\Users\Luís Pinto Coelho\Desktop\Dissertação\StudyScreening_Meta-Analysis\data\web_of_science\raw_data\savedrecs_1.xls | H18: 47 | I18: 2026-02-26 | J18: Juraev, DT; Amanov, OA; Dilmurodov, SD; Meyliev, AX; Boysunov; Buronov, A; Aminova, DX; Turaeva, SM | K18: 2024 | L18: BREAD WHEAT RESPONSE TO HEAT STRESS CONDITIONS FOR PRODUCTIVITY IN THE SOUTHERN REGIONS OF UZBEKISTAN | M18: Climate change and enhanced air temperatures adversely affect the wheat's (Triticum aestivum L.) morphological, physiological, biochemical, and molecular properties and grain yield. Therefore, developing high-yielding and resistant bread wheat cultivars to abiotic factors is vital, along with their primary source under varied environmental conditions. In the presented study, monitoring the influence of high temperatures (30 degrees & Scy; and above) continuously during the grain maturation period, especially in grain filling, on grain quality and productivity has undergone thorough research in the southern parts of Uzbekistan. These Southern regions mainly grow winter bread wheat cultivars. In determining the heat resistance of winter wheat cultivars typically planted in the Republic and selecting the best ones, the experiments and observations materialized with optimum and late-sowing conditions. The study determined the temperature during the growth period and daily temperatures during the grain-filling period. The research was able to evaluate the influence of air temperatures on 1000-grain weight, grain nature, and protein and gluten content and compare the results under optimum and late periods. | N18: Bread wheat (T. aestivum L.); cultivars; climate change; high temperature; heat resistance; growth phases; grain-filling period; grain yield and quality | O18: SABRAO JOURNAL OF BREEDING AND GENETICS | P18: 56 | Q18: 5 | R18: 1834 | S18: 1844 | U18: jurayevdiyor9@gmail.com; di.yor@mail.ru; s.dilmurodov@mail.ru; akmal_8417@mail.ru; nurzod.boysunov@mail.ru; buronova_1985@mail.ru; dildoraminova8@gmail.com; saidaicps@gmail.com | V18: 10.54910/sabrao2024.56.5.8 | W18: https://doi.org/10.54910/sabrao2024.56.5.8 | X18: 1 | Y18: downloaded | Z18: 33__BREAD_WHEAT_RESPONSE_TO_HEAT_STRESS_CONDITIONS_FOR_PRODUCTIVITY_IN_THE_SOUTHERN_REGIONS_OF_UZBEKISTAN.pdf | AA18: https://sabraojournal.org/wp-content/uploads/2024/10/SABRAO-J-Breed-Genet-56-5-1834-1844-MS24-44.pdf | AB18: pdf_files/33__BREAD_WHEAT_RESPONSE_TO_HEAT_STRESS_CONDITIONS_FOR_PRODUCTIVITY_IN_THE_SOUTHERN_REGIONS_OF_UZBEKISTAN.pdf | AC18: 200 | AD18: 2026-03-15 11:25:09 | AE18: =IFERROR(IF(ISBLANK(INDEX(wos_screening_view_full_text!$O:$O, MATCH($A18, wos_screening_view_full_text!$B:$B, 0))), "", INDEX(wos_screening_view_full_text!$O:$O, MATCH($A18, wos_screening_view_full_text!$B:$B, 0))), "") | AF18: =IFERROR(IF(ISBLANK(INDEX(wos_screening_view_full_text!$P:$P, MATCH($A18, wos_screening_view_full_text!$B:$B, 0))), "", INDEX(wos_screening_view_full_text!$P:$P, MATCH($A18, wos_screening_view_full_text!$B:$B, 0))), "") | AG18: =IFERROR(IF(ISBLANK(INDEX(wos_screening_view_full_text!$Q:$Q, MATCH($A18, wos_screening_view_full_text!$B:$B, 0))), "", INDEX(wos_screening_view_full_text!$Q:$Q, MATCH($A18, wos_screening_view_full_text!$B:$B, 0))), "")
